Workbook

Sheet OWNER SETTINGS
A1: Small Business Capital Decision Settings
A3: Setting | B3: Your Input | D3: What is the discount rate?
A4: Discount rate used for NPV | B4: 0.1 | D4: NPV converts future cash benefits into today's dollars. The discount rate is the return you require to justify tying up your money. The 10% starting value is only a placeholder for the pilot. If you have a business loan or a return target you normally use, replace 10% with a rate that better reflects your situation.
A5: Financial score weight | B5: 0.4
A6: Execution score weight | B6: 0.2
A7: Readiness score weight | B7: 0.15
A8: Operational need score weight | B8: 0.15
A9: Strategic fit score weight | B9: 0.1
A11: Weight Check | B11: =SUM(B5:B9) -> 1

Sheet START HERE
A1: Capital Decision Toolkit for Small Business Owners
A3: You do NOT need a finance background to use this workbook. Enter the information you already know about a project — what it costs, what extra cash or savings it may create, whether you are ready to do it, and what could go wrong. The workbook does the NPV and scoring calculations for you.
A6: Use the toolkit in this order
A7: Step | B7: What you do | C7: Sheet
A8: 1 | B8: If you need help estimating annual cash benefit, use the simple cash helper. | C8: CASH BENEFIT HELPER
A9: 2 | B9: Enter project cost and expected cash benefit for up to five years. NPV and payback calculate automatically. | C9: MONEY CALCULATOR
A10: 3 | B10: Answer six readiness questions and score each project using simple 1–5 questions. | C10: OWNER SCORECARD
A11: 4 | B11: Compare the projects in one place and record what you decided. | C11: RESULTS
A12: 5 | B12: After you invest, compare what actually happened with what you expected. | C12: POST-INVESTMENT CHECK-IN
A13: 6 | B13: After testing the toolkit, tell us what was useful, confusing, or worth keeping. | C13: PILOT FEEDBACK
A15: Three simple finance ideas used in this workbook
A16: Term | B16: Plain-English meaning | D16: Example: You are considering a $12,000 piece of equipment. You expect it to create $5,000 of extra net cash each year for five years. You enter the $12,000 cost and the five yearly cash benefits. The workbook discounts those future benefits and automatically tells you the NPV. You do not need to know the NPV formula to use the tool.
A17: Net cash benefit | B17: Extra cash the project puts in your pocket after the extra cash costs it creates. It can also include cash savings.
A18: NPV | B18: What the future cash benefits are worth today after allowing for time and the return you require. Positive NPV is generally better than negative NPV.
A19: Simple payback | B19: Roughly how many years of average cash benefit it takes to recover the money you put in upfront.
A21: Important
A22: This workbook helps organize a decision; it does not make the decision for you and is not tax, accounting, legal, or investment advice. Use your own judgment and validate important assumptions before committing money.
A26: NEW: Want to see a fully completed example first? Open the SIMPLE SME EXAMPLE sheet.
A28: New: not sure how this fits your business? Open 'ADAPT TO YOUR BUSINESS'. Want to see it applied? Open 'EXAMPLES 3 BUSINESS TYPES'.
A30: Version: Toolkit v3.1 — External Pilot Version (frozen for distribution).

Sheet ADAPT TO YOUR BUSINESS
A1: This toolkit works for ANY small business
A2: The steps are the same whatever you do. Only the examples change. Use the prompts below to map the toolkit to your own business — then enter your own numbers in the MONEY CALCULATOR and OWNER SCORECARD.
A4: Toolkit idea | B4: How to think about it for your business
A5: A 'project' | B5: Any use of cash you're weighing: equipment, a hire, a renovation, software, a new location, more inventory, a marketing push, a vehicle.
A6: 'Cash benefit' | B6: Extra money the project puts in your pocket: more sales, higher prices, OR money saved (less waste, lower rent, fewer repairs, less outsourcing).
A7: 'Upfront cost' | B7: Everything you pay to get started: purchase price, setup, install, deposits, initial stock, training.
A8: 'Readiness' | B8: Do you understand the cost, the payoff, how you'll pay for it, the steps, and who's responsible? If not, pause until you do.
A9: 'Strategic fit' | B9: Does this move the business in the direction you actually want to grow?
A11: Examples of a 'project' by business type
A12: Product / retail / maker | B12: New equipment, more inventory, a second location, packaging line, point-of-sale system.
A13: Food / cafe / hospitality | B13: Roaster or oven, kitchen build-out, delivery capability, extra seating, online ordering.
A14: Service / professional firm | B14: A new hire, software/tooling, office space, certification, a marketing or lead-gen push.
A15: Trades / field business | B15: A vehicle, tools/equipment, a crew member, scheduling software, a storage yard.
A17: Tip

Sheet EXAMPLES 3 BUSINESS TYPES
A1: Three worked examples — different business types
A2: All numbers are fictional and illustrative only, and use the toolkit's 5-year, 10% model so they reconcile. They show how the SAME toolkit applies across different businesses. Open MONEY CALCULATOR to run your own.
A4: Example 1 — Product / maker business (home-goods maker)
A5: Project | B5: Upfront $ | C5: Y1 | D5: Y2 | E5: Y3 | F5: Y4 | G5: Y5 | H5: NPV @10% | I5: Payback (yrs) | J5: Plain-English read
A6: Buy production equipment | B6: 18000 | C6: 7000 | D6: 8000 | E6: 8500 | F6: 8500 | G6: 8500 | H6: 12445 | I6: 2.2 | J6: Strong payoff; fund if readiness is high
A7: Upgrade e-commerce | B7: 10000 | C7: 4500 | D7: 5500 | E7: 6500 | F7: 7000 | G7: 7000 | H7: 12647 | I7: 1.6 | J7: Best return + fast payback; strong fit
A8: Replace aging equipment | B8: 14000 | C8: 4000 | D8: 4500 | E8: 5000 | F8: 5000 | G8: 5000 | H8: 3632 | I8: 3 | J8: Lower return but may be a reliability 'must-do'
A10: Example 2 — Food / cafe business (small coffee roaster)
A11: Project | B11: Upfront $ | C11: Y1 | D11: Y2 | E11: Y3 | F11: Y4 | G11: Y5 | H11: NPV @10% | I11: Payback (yrs) | J11: Plain-English read
A12: Small roasting setup | B12: 15000 | C12: 8700 | D12: 8700 | E12: 8700 | F12: 8700 | G12: 8700 | H12: 17980 | I12: 1.7 | J12: Strong NPV; cuts outsourcing, adds capacity
A13: Extra seating / fit-out | B13: 9000 | C13: 3000 | D13: 3200 | E13: 3400 | F13: 3400 | G13: 3400 | H13: 3360 | I13: 2.7 | J13: Modest return; weigh against roaster first
A14: Online ordering + delivery | B14: 4000 | C14: 2500 | D14: 3000 | E14: 3200 | F14: 3200 | G14: 3200 | H14: 7329 | I14: 1.3 | J14: Low cost, quick payback; easy early win
A16: Example 3 — Service / professional firm (small studio)
A17: Project | B17: Upfront $ | C17: Y1 | D17: Y2 | E17: Y3 | F17: Y4 | G17: Y5 | H17: NPV @10% | I17: Payback (yrs) | J17: Plain-English read
A18: Hire one specialist | B18: 60000 | C18: 28000 | D18: 34000 | E18: 38000 | F18: 38000 | G18: 38000 | H18: 71653 | I18: 1.7 | J18: Capacity + revenue; check you can keep them busy
A19: Project / accounting software | B19: 6000 | C19: 3500 | D19: 3800 | E19: 4000 | F19: 4000 | G19: 4000 | H19: 8543 | I19: 1.6 | J19: Cheap, fast payback, improves margins
A20: Larger office lease | B20: 40000 | C20: 10000 | D20: 12000 | E20: 14000 | F20: 14000 | G20: 14000 | H20: 7782 | I20: 3.1 | J20: Check NPV before committing; stage if thin
A22: In every case the highest NPV is not automatically funded first: a reliability 'must-do' or a cheap quick win can rank ahead. That judgment is the point of the OWNER SCORECARD and RESULTS sheets.

Sheet CASH BENEFIT HELPER
A1: Simple Annual Cash Benefit Helper
A2: Use this only if you need help estimating the yearly cash benefit. Enter cash you expect to come IN because of the project, cash that will go OUT because of the project, and any yearly savings. The result is a simple annual net cash benefit estimate.
A5: Project | B5: Extra cash in per month ($) | C5: Extra cash expenses per month ($) | D5: Annual cash savings ($) | E5: Other annual costs ($) | F5: Estimated annual net cash benefit ($) | G5: Suggested Year 1 cash benefit ($) | H5: Notes | I5: Example of what to include
F6: =IF(A6="","",(B6-C6)*12+D6-E6) | G6: =IF(A6="","",F6) | I6: Sales, service fees, subscriptions, wholesale orders, etc.
F7: =IF(A7="","",(B7-C7)*12+D7-E7) | G7: =IF(A7="","",F7) | I7: Materials, extra labor, delivery, platform fees, utilities, etc.
F8: =IF(A8="","",(B8-C8)*12+D8-E8) | G8: =IF(A8="","",F8) | I8: Rent savings, lower waste, fewer repairs, lower contractor cost, etc.
F9: =IF(A9="","",(B9-C9)*12+D9-E9) | G9: =IF(A9="","",F9) | I9: Maintenance, software, insurance, licensing, recurring fees, etc.
F10: =IF(A10="","",(B10-C10)*12+D10-E10) | G10: =IF(A10="","",F10) | I10: Use your best estimate; you can update it later.

Sheet MONEY CALCULATOR
A1: Project Money Calculator — NPV & Payback
A2: For each project, enter the upfront cost and the NET CASH BENEFIT you expect in each year. Net cash benefit means extra cash/savings AFTER the extra cash costs caused by the project. If you expect the same amount each year, repeat the same number across Years 1–5.
A5: Project | B5: What are you considering? | C5: Purchase / setup cost now ($) | D5: Other upfront costs ($) | E5: Total cash needed today ($) | F5: Year 1 net cash benefit ($) | G5: Year 2 ($) | H5: Year 3 ($) | I5: Year 4 ($) | J5: Year 5 ($) | K5: Discount rate | L5: NPV ($) | M5: Average annual net cash benefit ($) | N5: Simple payback (yrs) | O5: Plain-English result
E6: =IF(A6="","",C6+D6) | K6: ='OWNER SETTINGS'!$B$4 -> 0.1 | L6: =IF(A6="","",-E6+F6/(1+K6)^1+G6/(1+K6)^2+H6/(1+K6)^3+I6/(1+K6)^4+J6/(1+K6)^5) | M6: =IF(A6="","",AVERAGE(F6:J6)) | N6: =IF(OR(A6="",M6<=0),"",E6/M6) | O6: =IF(A6="","",IF(L6>0,"Positive NPV: expected cash benefits exceed the required return.",IF(L6=0,"Around break-even at the selected discount rate.","Negative NPV: expected cash benefits may not justify the upfront cost at this return target.")))
E7: =IF(A7="","",C7+D7) | K7: ='OWNER SETTINGS'!$B$4 -> 0.1 | L7: =IF(A7="","",-E7+F7/(1+K7)^1+G7/(1+K7)^2+H7/(1+K7)^3+I7/(1+K7)^4+J7/(1+K7)^5) | M7: =IF(A7="","",AVERAGE(F7:J7)) | N7: =IF(OR(A7="",M7<=0),"",E7/M7) | O7: =IF(A7="","",IF(L7>0,"Positive NPV: expected cash benefits exceed the required return.",IF(L7=0,"Around break-even at the selected discount rate.","Negative NPV: expected cash benefits may not justify the upfront cost at this return target.")))
E8: =IF(A8="","",C8+D8) | K8: ='OWNER SETTINGS'!$B$4 -> 0.1 | L8: =IF(A8="","",-E8+F8/(1+K8)^1+G8/(1+K8)^2+H8/(1+K8)^3+I8/(1+K8)^4+J8/(1+K8)^5) | M8: =IF(A8="","",AVERAGE(F8:J8)) | N8: =IF(OR(A8="",M8<=0),"",E8/M8) | O8: =IF(A8="","",IF(L8>0,"Positive NPV: expected cash benefits exceed the required return.",IF(L8=0,"Around break-even at the selected discount rate.","Negative NPV: expected cash benefits may not justify the upfront cost at this return target.")))
E9: =IF(A9="","",C9+D9) | K9: ='OWNER SETTINGS'!$B$4 -> 0.1 | L9: =IF(A9="","",-E9+F9/(1+K9)^1+G9/(1+K9)^2+H9/(1+K9)^3+I9/(1+K9)^4+J9/(1+K9)^5) | M9: =IF(A9="","",AVERAGE(F9:J9)) | N9: =IF(OR(A9="",M9<=0),"",E9/M9) | O9: =IF(A9="","",IF(L9>0,"Positive NPV: expected cash benefits exceed the required return.",IF(L9=0,"Around break-even at the selected discount rate.","Negative NPV: expected cash benefits may not justify the upfront cost at this return target.")))
E10: =IF(A10="","",C10+D10) | K10: ='OWNER SETTINGS'!$B$4 -> 0.1 | L10: =IF(A10="","",-E10+F10/(1+K10)^1+G10/(1+K10)^2+H10/(1+K10)^3+I10/(1+K10)^4+J10/(1+K10)^5) | M10: =IF(A10="","",AVERAGE(F10:J10)) | N10: =IF(OR(A10="",M10<=0),"",E10/M10) | O10: =IF(A10="","",IF(L10>0,"Positive NPV: expected cash benefits exceed the required return.",IF(L10=0,"Around break-even at the selected discount rate.","Negative NPV: expected cash benefits may not justify the upfront cost at this return target.")))
A13: NPV formula used by the workbook
A14: NPV = - cash paid today + Year 1 cash benefit ÷ (1 + discount rate)^1 + Year 2 cash benefit ÷ (1 + discount rate)^2 + ... through Year 5. The workbook performs this automatically. You only need to estimate the cash amounts.

Sheet OWNER SCORECARD
A1: Small Business Decision Scorecard
A2: First answer the six readiness questions. A 'No' means the project should usually be paused until that information is clearer. If the project passes, score the five decision questions from 1 (weak) to 5 (strong).
A5: Project | B5: Do I understand the full cost? | C5: Do I have a realistic cash benefit estimate? | D5: Do I know how I will pay for it? | E5: Do I know the steps/timing to get started? | F5: Do I have the time/people/capacity to execute? | G5: Have I identified the main risks? | H5: Readiness Gate | I5: Money: Does it create enough value? (1-5) | J5: Delivery: Can we actually get it done? (1-5) | K5: Ready now: Are key pieces in place? (1-5) | L5: Need: What happens if we wait/do nothing? (1-5) | M5: Fit: Does this support where the business is going? (1-5) | N5: Overall Score | O5: Rank | P5: Decision | Q5: Owner Notes | R5: NPV ($) | S5: Simple Payback (yrs) | T5: Upfront Cost ($) | U5: Discount Rate
A6: =IF('MONEY CALCULATOR'!A6="","",'MONEY CALCULATOR'!A6) | H6: =IF(A6="","",IF(COUNTIF(B6:G6,"No")>0,"PAUSE",IF(COUNTBLANK(B6:G6)>0,"INCOMPLETE","READY"))) | N6: =IF(H6<>"READY","",I6*'OWNER SETTINGS'!$B$5+J6*'OWNER SETTINGS'!$B$6+K6*'OWNER SETTINGS'!$B$7+L6*'OWNER SETTINGS'!$B$8+M6*'OWNER SETTINGS'!$B$9) | O6: =IF(H6<>"READY","",1+COUNTIFS($H$6:$H$10,"READY",$N$6:$N$10,">"&N6)) | R6: =IF('MONEY CALCULATOR'!L6="","",'MONEY CALCULATOR'!L6) | S6: =IF('MONEY CALCULATOR'!N6="","",'MONEY CALCULATOR'!N6) | T6: =IF('MONEY CALCULATOR'!E6="","",'MONEY CALCULATOR'!E6) | U6: ='MONEY CALCULATOR'!K6 -> 0.1
A7: =IF('MONEY CALCULATOR'!A7="","",'MONEY CALCULATOR'!A7) | H7: =IF(A7="","",IF(COUNTIF(B7:G7,"No")>0,"PAUSE",IF(COUNTBLANK(B7:G7)>0,"INCOMPLETE","READY"))) | N7: =IF(H7<>"READY","",I7*'OWNER SETTINGS'!$B$5+J7*'OWNER SETTINGS'!$B$6+K7*'OWNER SETTINGS'!$B$7+L7*'OWNER SETTINGS'!$B$8+M7*'OWNER SETTINGS'!$B$9) | O7: =IF(H7<>"READY","",1+COUNTIFS($H$6:$H$10,"READY",$N$6:$N$10,">"&N7)) | R7: =IF('MONEY CALCULATOR'!L7="","",'MONEY CALCULATOR'!L7) | S7: =IF('MONEY CALCULATOR'!N7="","",'MONEY CALCULATOR'!N7) | T7: =IF('MONEY CALCULATOR'!E7="","",'MONEY CALCULATOR'!E7) | U7: ='MONEY CALCULATOR'!K7 -> 0.1
A8: =IF('MONEY CALCULATOR'!A8="","",'MONEY CALCULATOR'!A8) | H8: =IF(A8="","",IF(COUNTIF(B8:G8,"No")>0,"PAUSE",IF(COUNTBLANK(B8:G8)>0,"INCOMPLETE","READY"))) | N8: =IF(H8<>"READY","",I8*'OWNER SETTINGS'!$B$5+J8*'OWNER SETTINGS'!$B$6+K8*'OWNER SETTINGS'!$B$7+L8*'OWNER SETTINGS'!$B$8+M8*'OWNER SETTINGS'!$B$9) | O8: =IF(H8<>"READY","",1+COUNTIFS($H$6:$H$10,"READY",$N$6:$N$10,">"&N8)) | R8: =IF('MONEY CALCULATOR'!L8="","",'MONEY CALCULATOR'!L8) | S8: =IF('MONEY CALCULATOR'!N8="","",'MONEY CALCULATOR'!N8) | T8: =IF('MONEY CALCULATOR'!E8="","",'MONEY CALCULATOR'!E8) | U8: ='MONEY CALCULATOR'!K8 -> 0.1
A9: =IF('MONEY CALCULATOR'!A9="","",'MONEY CALCULATOR'!A9) | H9: =IF(A9="","",IF(COUNTIF(B9:G9,"No")>0,"PAUSE",IF(COUNTBLANK(B9:G9)>0,"INCOMPLETE","READY"))) | N9: =IF(H9<>"READY","",I9*'OWNER SETTINGS'!$B$5+J9*'OWNER SETTINGS'!$B$6+K9*'OWNER SETTINGS'!$B$7+L9*'OWNER SETTINGS'!$B$8+M9*'OWNER SETTINGS'!$B$9) | O9: =IF(H9<>"READY","",1+COUNTIFS($H$6:$H$10,"READY",$N$6:$N$10,">"&N9)) | R9: =IF('MONEY CALCULATOR'!L9="","",'MONEY CALCULATOR'!L9) | S9: =IF('MONEY CALCULATOR'!N9="","",'MONEY CALCULATOR'!N9) | T9: =IF('MONEY CALCULATOR'!E9="","",'MONEY CALCULATOR'!E9) | U9: ='MONEY CALCULATOR'!K9 -> 0.1
A10: =IF('MONEY CALCULATOR'!A10="","",'MONEY CALCULATOR'!A10) | H10: =IF(A10="","",IF(COUNTIF(B10:G10,"No")>0,"PAUSE",IF(COUNTBLANK(B10:G10)>0,"INCOMPLETE","READY"))) | N10: =IF(H10<>"READY","",I10*'OWNER SETTINGS'!$B$5+J10*'OWNER SETTINGS'!$B$6+K10*'OWNER SETTINGS'!$B$7+L10*'OWNER SETTINGS'!$B$8+M10*'OWNER SETTINGS'!$B$9) | O10: =IF(H10<>"READY","",1+COUNTIFS($H$6:$H$10,"READY",$N$6:$N$10,">"&N10)) | R10: =IF('MONEY CALCULATOR'!L10="","",'MONEY CALCULATOR'!L10) | S10: =IF('MONEY CALCULATOR'!N10="","",'MONEY CALCULATOR'!N10) | T10: =IF('MONEY CALCULATOR'!E10="","",'MONEY CALCULATOR'!E10) | U10: ='MONEY CALCULATOR'!K10 -> 0.1
A13: How to think about the 1–5 scores
A14: Score | B14: Money / value | C14: Can we deliver? | D14: Ready now? | E14: Need / cost of waiting | F14: Fit with business direction
A15: 1 | B15: Very weak economics | C15: Major obstacles / very hard | D15: Not ready | E15: Little downside to waiting | F15: Does not fit
A16: 2 | B16: Weak | C16: Several serious obstacles | D16: Many pieces missing | E16: Low downside | F16: Limited fit
A17: 3 | B17: Acceptable | C17: Manageable with work | D17: Mostly ready | E17: Moderate downside | F17: Reasonable fit
A18: 4 | B18: Strong | C18: Good delivery path | D18: Ready with minor gaps | E18: High downside to waiting | F18: Strong fit
A19: 5 | B19: Very strong | C19: Very confident in delivery | D19: Ready to go | E19: Critical / costly to delay | F19: Directly supports priority

Sheet RESULTS
A1: Your Project Comparison
A2: Use this page for the discussion. The financial result is important, but the highest NPV does not automatically mean the project should be first. Look at the readiness gate, overall score, cost of waiting, and your practical ability to execute.
A5: Project | B5: Readiness | C5: Upfront Cost ($) | D5: NPV ($) | E5: Payback (yrs) | F5: Overall Score | G5: Rank | H5: Your Decision | I5: Why? | J5: Next Step
A6: =IF('OWNER SCORECARD'!A6="","",'OWNER SCORECARD'!A6) | B6: =IF('OWNER SCORECARD'!H6="","",'OWNER SCORECARD'!H6) | C6: =IF('OWNER SCORECARD'!T6="","",'OWNER SCORECARD'!T6) | D6: =IF('OWNER SCORECARD'!R6="","",'OWNER SCORECARD'!R6) | E6: =IF('OWNER SCORECARD'!S6="","",'OWNER SCORECARD'!S6) | F6: =IF('OWNER SCORECARD'!N6="","",'OWNER SCORECARD'!N6) | G6: =IF('OWNER SCORECARD'!O6="","",'OWNER SCORECARD'!O6) | H6: =IF('OWNER SCORECARD'!P6="","",'OWNER SCORECARD'!P6) | I6: =IF('OWNER SCORECARD'!Q6="","",'OWNER SCORECARD'!Q6)
A7: =IF('OWNER SCORECARD'!A7="","",'OWNER SCORECARD'!A7) | B7: =IF('OWNER SCORECARD'!H7="","",'OWNER SCORECARD'!H7) | C7: =IF('OWNER SCORECARD'!T7="","",'OWNER SCORECARD'!T7) | D7: =IF('OWNER SCORECARD'!R7="","",'OWNER SCORECARD'!R7) | E7: =IF('OWNER SCORECARD'!S7="","",'OWNER SCORECARD'!S7) | F7: =IF('OWNER SCORECARD'!N7="","",'OWNER SCORECARD'!N7) | G7: =IF('OWNER SCORECARD'!O7="","",'OWNER SCORECARD'!O7) | H7: =IF('OWNER SCORECARD'!P7="","",'OWNER SCORECARD'!P7) | I7: =IF('OWNER SCORECARD'!Q7="","",'OWNER SCORECARD'!Q7)
A8: =IF('OWNER SCORECARD'!A8="","",'OWNER SCORECARD'!A8) | B8: =IF('OWNER SCORECARD'!H8="","",'OWNER SCORECARD'!H8) | C8: =IF('OWNER SCORECARD'!T8="","",'OWNER SCORECARD'!T8) | D8: =IF('OWNER SCORECARD'!R8="","",'OWNER SCORECARD'!R8) | E8: =IF('OWNER SCORECARD'!S8="","",'OWNER SCORECARD'!S8) | F8: =IF('OWNER SCORECARD'!N8="","",'OWNER SCORECARD'!N8) | G8: =IF('OWNER SCORECARD'!O8="","",'OWNER SCORECARD'!O8) | H8: =IF('OWNER SCORECARD'!P8="","",'OWNER SCORECARD'!P8) | I8: =IF('OWNER SCORECARD'!Q8="","",'OWNER SCORECARD'!Q8)
A9: =IF('OWNER SCORECARD'!A9="","",'OWNER SCORECARD'!A9) | B9: =IF('OWNER SCORECARD'!H9="","",'OWNER SCORECARD'!H9) | C9: =IF('OWNER SCORECARD'!T9="","",'OWNER SCORECARD'!T9) | D9: =IF('OWNER SCORECARD'!R9="","",'OWNER SCORECARD'!R9) | E9: =IF('OWNER SCORECARD'!S9="","",'OWNER SCORECARD'!S9) | F9: =IF('OWNER SCORECARD'!N9="","",'OWNER SCORECARD'!N9) | G9: =IF('OWNER SCORECARD'!O9="","",'OWNER SCORECARD'!O9) | H9: =IF('OWNER SCORECARD'!P9="","",'OWNER SCORECARD'!P9) | I9: =IF('OWNER SCORECARD'!Q9="","",'OWNER SCORECARD'!Q9)
A10: =IF('OWNER SCORECARD'!A10="","",'OWNER SCORECARD'!A10) | B10: =IF('OWNER SCORECARD'!H10="","",'OWNER SCORECARD'!H10) | C10: =IF('OWNER SCORECARD'!T10="","",'OWNER SCORECARD'!T10) | D10: =IF('OWNER SCORECARD'!R10="","",'OWNER SCORECARD'!R10) | E10: =IF('OWNER SCORECARD'!S10="","",'OWNER SCORECARD'!S10) | F10: =IF('OWNER SCORECARD'!N10="","",'OWNER SCORECARD'!N10) | G10: =IF('OWNER SCORECARD'!O10="","",'OWNER SCORECARD'!O10) | H10: =IF('OWNER SCORECARD'!P10="","",'OWNER SCORECARD'!P10) | I10: =IF('OWNER SCORECARD'!Q10="","",'OWNER SCORECARD'!Q10)

Sheet POST-INVESTMENT CHECK-IN
A1: After You Invest — Simple Check-In
A2: Come back after the project has been running long enough to learn something. The goal is not to prove the original decision was 'right' or 'wrong' — it is to compare expectations with reality and improve the next decision.
A5: Project | B5: Review date | C5: Expected upfront cost ($) | D5: Actual upfront cost ($) | E5: Cost difference ($) | F5: Expected Year 1 cash benefit ($) | G5: Actual / updated Year 1 cash benefit ($) | H5: Benefit difference ($) | I5: Planned start / launch | J5: Actual start / launch | K5: Delay (days) | L5: Overall outcome (1-5) | M5: What worked? | N5: What did not go as expected? | O5: Would you make the same investment again? | P5: What will you do differently next time?
E6: =IF(OR(C6="",D6=""),"",D6-C6) | H6: =IF(OR(F6="",G6=""),"",G6-F6) | K6: =IF(OR(I6="",J6=""),"",J6-I6)
E7: =IF(OR(C7="",D7=""),"",D7-C7) | H7: =IF(OR(F7="",G7=""),"",G7-F7) | K7: =IF(OR(I7="",J7=""),"",J7-I7)
E8: =IF(OR(C8="",D8=""),"",D8-C8) | H8: =IF(OR(F8="",G8=""),"",G8-F8) | K8: =IF(OR(I8="",J8=""),"",J8-I8)
E9: =IF(OR(C9="",D9=""),"",D9-C9) | H9: =IF(OR(F9="",G9=""),"",G9-F9) | K9: =IF(OR(I9="",J9=""),"",J9-I9)
E10: =IF(OR(C10="",D10=""),"",D10-C10) | H10: =IF(OR(F10="",G10=""),"",G10-F10) | K10: =IF(OR(I10="",J10=""),"",J10-I10)

Sheet PILOT FEEDBACK
A1: Tell Us How the Toolkit Worked for You
A2: Please answer based on your actual experience using the toolkit. There are no 'right' answers. The purpose is to learn what helps a small business owner make a better capital decision.
A5: Business / organization
A6: Your name (optional)
A7: Your role
A8: Date
A9: Project / decision tested
A10: Industry
A12: Statement | B12: Score (1-5) | C12: Comments
A13: I could use the toolkit without needing a finance background.
A14: The NPV / money section was understandable.
A15: The toolkit helped me compare options more clearly.
A16: It made me think about risks or missing information I had not written down before.
A17: It changed or clarified the order in which I would pursue projects.
A18: It influenced whether I would approve, stage, pause, or reject a project.
A19: I would use at least part of this toolkit again.
A20: I would recommend it to another small business owner.
A22: Question | B22: Your response
A23: What was the most useful part?
A24: What was confusing or harder than it needed to be?
A25: Did the toolkit change a decision or the timing of a decision? How?
A26: Which part would you use again?
A27: What should be added or removed for small business owners?

Sheet WORKED EXAMPLE
A1: Worked Example — Small Business Owner
A2: Illustrative numbers only. Imagine a small owner-operated consumer business comparing three uses of limited cash. The example shows how the workbook thinks about money AND practical execution.
A5: Project | B5: Cost now ($) | C5: Y1 cash benefit | D5: Y2 | E5: Y3 | F5: Y4 | G5: Y5 | H5: NPV at 10% | I5: Payback | J5: Money | K5: Delivery | L5: Ready | M5: Need | N5: Fit | O5: Overall Score
A6: Add production equipment | B6: 18000 | C6: 7000 | D6: 8000 | E6: 8500 | F6: 8500 | G6: 8500 | H6: =-B6+C6/(1+'OWNER SETTINGS'!$B$4)^1+D6/(1+'OWNER SETTINGS'!$B$4)^2+E6/(1+'OWNER SETTINGS'!$B$4)^3+F6/(1+'OWNER SETTINGS'!$B$4)^4+G6/(1+'OWNER SETTINGS'!$B$4)^5 -> 12444.828 | I6: =B6/AVERAGE(C6:G6) -> 2.2222222 | J6: 4 | K6: 3 | L6: 4 | M6: 3 | N6: 4 | O6: =J6*'OWNER SETTINGS'!$B$5+K6*'OWNER SETTINGS'!$B$6+L6*'OWNER SETTINGS'!$B$7+M6*'OWNER SETTINGS'!$B$8+N6*'OWNER SETTINGS'!$B$9 -> 3.65
A7: Upgrade e-commerce & fulfillment | B7: 10000 | C7: 4500 | D7: 5500 | E7: 6500 | F7: 7000 | G7: 7000 | H7: =-B7+C7/(1+'OWNER SETTINGS'!$B$4)^1+D7/(1+'OWNER SETTINGS'!$B$4)^2+E7/(1+'OWNER SETTINGS'!$B$4)^3+F7/(1+'OWNER SETTINGS'!$B$4)^4+G7/(1+'OWNER SETTINGS'!$B$4)^5 -> 12647.453 | I7: =B7/AVERAGE(C7:G7) -> 1.6393443 | J7: 4 | K7: 4 | L7: 5 | M7: 2 | N7: 5 | O7: =J7*'OWNER SETTINGS'!$B$5+K7*'OWNER SETTINGS'!$B$6+L7*'OWNER SETTINGS'!$B$7+M7*'OWNER SETTINGS'!$B$8+N7*'OWNER SETTINGS'!$B$9 -> 3.95
A8: Replace critical aging equipment | B8: 14000 | C8: 4000 | D8: 4500 | E8: 5000 | F8: 5000 | G8: 5000 | H8: =-B8+C8/(1+'OWNER SETTINGS'!$B$4)^1+D8/(1+'OWNER SETTINGS'!$B$4)^2+E8/(1+'OWNER SETTINGS'!$B$4)^3+F8/(1+'OWNER SETTINGS'!$B$4)^4+G8/(1+'OWNER SETTINGS'!$B$4)^5 -> 3631.6198 | I8: =B8/AVERAGE(C8:G8) -> 2.9787234 | J8: 3 | K8: 5 | L8: 5 | M8: 5 | N8: 4 | O8: =J8*'OWNER SETTINGS'!$B$5+K8*'OWNER SETTINGS'!$B$6+L8*'OWNER SETTINGS'!$B$7+M8*'OWNER SETTINGS'!$B$8+N8*'OWNER SETTINGS'!$B$9 -> 4.1
A10: Notice that the project with the strongest financial return does not automatically have to be the first project funded. A small business may reasonably prioritize an investment that is easier to deliver, urgently needed to keep the business operating, or better aligned with the owner's near-term strategy. The scorecard makes those trade-offs visible instead of leaving them in the owner's head.

Sheet SIMPLE SME EXAMPLE
A1: Simple Completed Example — A Small Coffee Business
A3: Fictional example only. Imagine an owner-operated coffee business considering whether to buy a small roasting and packaging setup. The owner does not calculate NPV by hand. They enter simple estimates they already understand, and the workbook converts those estimates into financial and decision information.
A7: STEP 1 — Describe the decision
A8: Question | B8: Owner's answer
A9: What am I considering? | B9: Buy a small roasting and packaging setup
A10: Why am I considering it? | B10: Reduce outsourced roasting, increase capacity, and support more direct sales
A11: How much cash do I need upfront? | B11: $15,000 total
A13: STEP 2 — Estimate the yearly cash benefit in plain English
A14: Owner estimate | B14: Amount | C14: What it means
A15: Extra sales expected each month | B15: 1800 | C15: Additional customer / wholesale sales
A16: Extra cash expenses each month | B16: 1100 | C16: Beans, packaging, transaction fees, extra labor, etc.
A17: Yearly cash savings | B17: 1200 | C17: Less outsourced roasting / other avoided cash costs
A18: Other yearly costs | B18: 900 | C18: Maintenance, supplies, recurring fees
A19: Estimated annual net cash benefit | B19: =(B15-B16)*12+B17-B18 -> 8700 | C19: This is what goes into the 5-year NPV calculation
A21: STEP 3 — Let the workbook calculate NPV and payback
A22: Input / result | B22: Year 0 | C22: Year 1 | D22: Year 2 | E22: Year 3 | F22: Year 4 | G22: Year 5 | H22: Meaning
A23: Cash flow | B23: -15000 | C23: =$B$19 -> 8700 | D23: =$B$19 -> 8700 | E23: =$B$19 -> 8700 | F23: =$B$19 -> 8700 | G23: =$B$19 -> 8700 | H23: Year 0 is the cash paid now; Years 1–5 are expected net cash benefits.
A24: Discount rate | B24: ='OWNER SETTINGS'!B4 -> 0.1 | H24: The toolkit currently uses the discount rate in OWNER SETTINGS.
A25: NPV | B25: =B23+C23/(1+B24)^1+D23/(1+B24)^2+E23/(1+B24)^3+F23/(1+B24)^4+G23/(1+B24)^5 -> 17979.845 | H25: Positive NPV means the expected cash benefits exceed the selected required return.
A26: Simple payback | B26: =ABS(B23)/AVERAGE(C23:G23) -> 1.7241379 | H26: Approximate years of average cash benefit needed to recover the upfront cash.
A27: Plain-English read | B27: =IF(B25>0,"The project has a positive NPV at the selected discount rate. That supports the financial case, but the owner should still consider readiness, risk, need, and strategic fit.","The project does not have a positive NPV at the selected discount rate.") -> The project has a positive NPV at the selected discount rate. That supports the financial case, but the owner should still consider readiness, risk, need, and strategic fit.
A30: STEP 4 — Ask the practical small-business questions
A31: Readiness question | B31: Answer | C31: Why | D31: Result | F31: Decision dimension | G31: Score | H31: Owner's reasoning
A32: Do I understand the full cost? | B32: Yes | C32: Purchase price and setup costs have been estimated. | F32: Money / value | G32: 4 | H32: Positive NPV and fairly quick payback.
A33: Do I have a realistic cash benefit estimate? | B33: Yes | C33: The owner used expected extra sales, costs, and savings. | F33: Can we deliver? | G33: 4 | H33: Implementation is manageable but still requires setup and learning.
A34: Do I know how I will pay for it? | B34: Yes | C34: The owner has identified the funding source. | F34: Ready now? | G34: 4 | H34: Most pieces are in place.
A35: Do I know the main implementation steps? | B35: Yes | C35: Equipment, setup, training, and launch steps are known. | F35: Need / cost of waiting | G35: 3 | H35: Helpful, but the business can continue without it for a while.
A36: Do I have time / people / capacity? | B36: Yes | C36: The owner believes current staffing can absorb the change. | F36: Fit with business direction | G36: 5 | H36: Supports more in-house production and direct growth.
A37: Have I identified the main risks? | B37: Yes | C37: Demand, equipment downtime, and supplier risk are understood. | F37: Overall score | G37: =G32*'OWNER SETTINGS'!B5+G33*'OWNER SETTINGS'!B6+G34*'OWNER SETTINGS'!B7+G35*'OWNER SETTINGS'!B8+G36*'OWNER SETTINGS'!B9 -> 3.95 | H37: Weighted using the toolkit's standard weights.
A38: Readiness gate | D38: =IF(COUNTIF(B32:B37,"No")>0,"PAUSE","READY") -> READY
A40: STEP 5 — Make and document the decision
A41: Item | B41: Example conclusion | D41: Why this matters: the spreadsheet did not ask the owner to know finance formulas. The owner supplied understandable business estimates. The toolkit calculated the finance result, then forced a separate conversation about execution, readiness, urgency, and strategic fit. The owner still makes the final decision.
A42: Financial result | B42: ="NPV: "&TEXT(B25,"$#,##0")&" | Payback: "&TEXT(B26,"0.0")&" years" -> NPV: $17,980 | Payback: 1.7 years
A43: Readiness result | B43: =D38 -> READY
A44: Overall score | B44: =TEXT(G37,"0.00")&" out of 5.00" -> 3.95 out of 5.00
A45: Owner decision | B45: APPROVE — move forward, but monitor whether the extra sales actually materialize.
A47: STEP 6 — Check what happened later
A48: After 6–12 months | B48: Original expectation | C48: Illustrative actual | D48: What the owner learns
A49: Upfront cost | B49: 15000 | C49: 15750 | D49: Setup cost was slightly higher than expected.
A50: Year 1 net cash benefit | B50: =$B$19 -> 8700 | C50: 8100 | D50: Actual benefit was below the original estimate.
...
